[2024-03-22T06:49:30.990+0000] {taskinstance.py:1979} INFO - Dependencies all met for dep_context=non-requeueable deps ti=<TaskInstance: first_dag.bash_task manual__2024-03-22T06:49:17.653423+00:00 [queued]>
[2024-03-22T06:49:31.001+0000] {taskinstance.py:1979} INFO - Dependencies all met for dep_context=requeueable deps ti=<TaskInstance: first_dag.bash_task manual__2024-03-22T06:49:17.653423+00:00 [queued]>
[2024-03-22T06:49:31.002+0000] {taskinstance.py:2193} INFO - Starting attempt 1 of 1
[2024-03-22T06:49:31.022+0000] {taskinstance.py:2217} INFO - Executing <Task(BashOperator): bash_task> on 2024-03-22 06:49:17.653423+00:00
[2024-03-22T06:49:31.030+0000] {standard_task_runner.py:60} INFO - Started process 5927 to run task
[2024-03-22T06:49:31.033+0000] {standard_task_runner.py:87} INFO - Running: ['***', 'tasks', 'run', 'first_dag', 'bash_task', 'manual__2024-03-22T06:49:17.653423+00:00', '--job-id', '34', '--raw', '--subdir', 'DAGS_FOLDER/main.py', '--cfg-path', '/tmp/tmp0b_sfsl4']
[2024-03-22T06:49:31.037+0000] {standard_task_runner.py:88} INFO - Job 34: Subtask bash_task
[2024-03-22T06:49:31.106+0000] {task_command.py:423} INFO - Running <TaskInstance: first_dag.bash_task manual__2024-03-22T06:49:17.653423+00:00 [running]> on host 35b78281a15e
[2024-03-22T06:49:31.162+0000] {abstractoperator.py:707} ERROR - Exception rendering Jinja template for task 'bash_task', field 'env'. Template: {'message': '{{ dag_run.conf["message"] if dag_run else "" }}'}
Traceback (most recent call last):
  File "/home/airflow/.local/lib/python3.8/site-packages/airflow/models/abstractoperator.py", line 699, in _do_render_template_fields
    rendered_content = self.render_template(
  File "/home/airflow/.local/lib/python3.8/site-packages/airflow/template/templater.py", line 186, in render_template
    return {k: self.render_template(v, context, jinja_env, oids) for k, v in value.items()}
  File "/home/airflow/.local/lib/python3.8/site-packages/airflow/template/templater.py", line 186, in <dictcomp>
    return {k: self.render_template(v, context, jinja_env, oids) for k, v in value.items()}
  File "/home/airflow/.local/lib/python3.8/site-packages/airflow/template/templater.py", line 174, in render_template
    return self._render(template, context)
  File "/home/airflow/.local/lib/python3.8/site-packages/airflow/models/abstractoperator.py", line 654, in _render
    return super()._render(template, context, dag=dag)
  File "/home/airflow/.local/lib/python3.8/site-packages/airflow/template/templater.py", line 131, in _render
    return render_template_to_string(template, context)
  File "/home/airflow/.local/lib/python3.8/site-packages/airflow/utils/helpers.py", line 289, in render_template_to_string
    return render_template(template, cast(MutableMapping[str, Any], context), native=False)
  File "/home/airflow/.local/lib/python3.8/site-packages/airflow/utils/helpers.py", line 284, in render_template
    return "".join(nodes)
  File "<template>", line 12, in root
  File "/home/airflow/.local/lib/python3.8/site-packages/jinja2/runtime.py", line 852, in _fail_with_undefined_error
    raise self._undefined_exception(self._undefined_message)
jinja2.exceptions.UndefinedError: 'dict object' has no attribute 'message'
[2024-03-22T06:49:31.169+0000] {taskinstance.py:2731} ERROR - Task failed with exception
Traceback (most recent call last):
  File "/home/airflow/.local/lib/python3.8/site-packages/airflow/models/taskinstance.py", line 2360, in _run_raw_task
    self._execute_task_with_callbacks(context, test_mode, session=session)
  File "/home/airflow/.local/lib/python3.8/site-packages/airflow/models/taskinstance.py", line 2498, in _execute_task_with_callbacks
    task_orig = self.render_templates(context=context)
  File "/home/airflow/.local/lib/python3.8/site-packages/airflow/models/taskinstance.py", line 2910, in render_templates
    original_task.render_template_fields(context)
  File "/home/airflow/.local/lib/python3.8/site-packages/airflow/models/baseoperator.py", line 1241, in render_template_fields
    self._do_render_template_fields(self, self.template_fields, context, jinja_env, set())
  File "/home/airflow/.local/lib/python3.8/site-packages/airflow/utils/session.py", line 79, in wrapper
    return func(*args, session=session, **kwargs)
  File "/home/airflow/.local/lib/python3.8/site-packages/airflow/models/abstractoperator.py", line 699, in _do_render_template_fields
    rendered_content = self.render_template(
  File "/home/airflow/.local/lib/python3.8/site-packages/airflow/template/templater.py", line 186, in render_template
    return {k: self.render_template(v, context, jinja_env, oids) for k, v in value.items()}
  File "/home/airflow/.local/lib/python3.8/site-packages/airflow/template/templater.py", line 186, in <dictcomp>
    return {k: self.render_template(v, context, jinja_env, oids) for k, v in value.items()}
  File "/home/airflow/.local/lib/python3.8/site-packages/airflow/template/templater.py", line 174, in render_template
    return self._render(template, context)
  File "/home/airflow/.local/lib/python3.8/site-packages/airflow/models/abstractoperator.py", line 654, in _render
    return super()._render(template, context, dag=dag)
  File "/home/airflow/.local/lib/python3.8/site-packages/airflow/template/templater.py", line 131, in _render
    return render_template_to_string(template, context)
  File "/home/airflow/.local/lib/python3.8/site-packages/airflow/utils/helpers.py", line 289, in render_template_to_string
    return render_template(template, cast(MutableMapping[str, Any], context), native=False)
  File "/home/airflow/.local/lib/python3.8/site-packages/airflow/utils/helpers.py", line 284, in render_template
    return "".join(nodes)
  File "<template>", line 12, in root
  File "/home/airflow/.local/lib/python3.8/site-packages/jinja2/runtime.py", line 852, in _fail_with_undefined_error
    raise self._undefined_exception(self._undefined_message)
jinja2.exceptions.UndefinedError: 'dict object' has no attribute 'message'
[2024-03-22T06:49:31.182+0000] {taskinstance.py:1149} INFO - Marking task as FAILED. dag_id=first_dag, task_id=bash_task, execution_date=20240322T064917, start_date=20240322T064930, end_date=20240322T064931
[2024-03-22T06:49:31.200+0000] {standard_task_runner.py:107} ERROR - Failed to execute job 34 for task bash_task ('dict object' has no attribute 'message'; 5927)
[2024-03-22T06:49:31.248+0000] {local_task_job_runner.py:234} INFO - Task exited with return code 1
[2024-03-22T06:49:31.282+0000] {taskinstance.py:3312} INFO - 0 downstream tasks scheduled from follow-on schedule check
